Workbook

Sheet Table 1
B2: Table 1. Summary Statistics for LEHD Samples
E4: Full sample | F4: Industry stayers | G4: Industry switchers | H4: Event study sample
E5: -1 | F5: -2 | G5: -3 | H5: -4
B6: Mean quarterly earnings | D6: ='disclosed1-1'!A7 -> lne | E6: =VALUE('disclosed1-1'!B7) -> 15510 | F6: =VALUE('disclosed1-1'!C7) -> 16050 | G6: =VALUE('disclosed1-1'!D7) -> 14630 | H6: =VALUE('disclosed1-1'!E7) -> 16350
B7: (standard deviation) | E7: =VALUE('disclosed1-1'!B8) -> -18020 | F7: =VALUE('disclosed1-1'!C8) -> -19710 | G7: =VALUE('disclosed1-1'!D8) -> -14860 | H7: =VALUE('disclosed1-1'!E8) -> -45670
B8: Mean age | D8: ='disclosed1-1'!A9 -> age | E8: =VALUE('disclosed1-1'!B9) -> 42.43 | F8: =VALUE('disclosed1-1'!C9) -> 44.04 | G8: =VALUE('disclosed1-1'!D9) -> 39.85 | H8: =VALUE('disclosed1-1'!E9)*40 +40 -> 40.04928
E9: =VALUE('disclosed1-1'!B10) -> -10.78 | F9: =VALUE('disclosed1-1'!C10) -> -10.71 | G9: =VALUE('disclosed1-1'!D10) -> -10.39 | H9: =VALUE('disclosed1-1'!E10)*40 -> -10.524
B10: Fraction female | D10: ='disclosed1-1'!A11 -> Gender | E10: =VALUE('disclosed1-1'!B11) -> 0.4734 | F10: =VALUE('disclosed1-1'!C11) -> 0.4839 | G10: =VALUE('disclosed1-1'!D11) -> 0.4565 | H10: =VALUE('disclosed1-1'!E11) -> 0.4629
E11: =VALUE('disclosed1-1'!B12) -> -0.4993 | F11: =VALUE('disclosed1-1'!C12) -> -0.4997 | G11: =VALUE('disclosed1-1'!D12) -> -0.4981 | H11: =VALUE('disclosed1-1'!E12) -> -0.4986
B12: Fraction foreign born | D12: ='disclosed1-1'!A13 -> forborn | E12: =VALUE('disclosed1-1'!B13) -> 0.1607 | F12: =VALUE('disclosed1-1'!C13) -> 0.1632 | G12: =VALUE('disclosed1-1'!D13) -> 0.1566 | H12: =VALUE('disclosed1-1'!E13) -> 0.143
E13: =VALUE('disclosed1-1'!B14) -> -0.3672 | F13: =VALUE('disclosed1-1'!C14) -> -0.3695 | G13: =VALUE('disclosed1-1'!D14) -> -0.3634 | H13: =VALUE('disclosed1-1'!E14) -> -0.3501
B14: Hispanic | D14: ='disclosed1-1'!A15 -> hisp | E14: =VALUE('disclosed1-1'!B15) -> 0.1334 | F14: =VALUE('disclosed1-1'!C15) -> 0.1295 | G14: =VALUE('disclosed1-1'!D15) -> 0.1396 | H14: =VALUE('disclosed1-1'!E15) -> 0.1228
E15: =VALUE('disclosed1-1'!B16) -> -0.34 | F15: =VALUE('disclosed1-1'!C16) -> -0.3358 | G15: =VALUE('disclosed1-1'!D16) -> -0.3466 | H15: =VALUE('disclosed1-1'!E16) -> -0.3282
B16: Number of CZs in which observed:
C17: 1 | D17: ='disclosed1-1'!A17 -> czcnt1 | E17: =VALUE('disclosed1-1'!B17) -> 0.786 | F17: =VALUE('disclosed1-1'!C17) -> 0.824 | G17: =VALUE('disclosed1-1'!D17) -> 0.7248 | H17: =VALUE('disclosed1-1'!E17) -> 0.9993
E18: =VALUE('disclosed1-1'!B18) -> -0.4101 | F18: =VALUE('disclosed1-1'!C18) -> -0.3808 | G18: =VALUE('disclosed1-1'!D18) -> -0.4466 | H18: =VALUE('disclosed1-1'!E18) -> -0.02634
C19: 2 | D19: ='disclosed1-1'!A19 -> czcnt2 | E19: =VALUE('disclosed1-1'!B19) -> 0.1734 | F19: =VALUE('disclosed1-1'!C19) -> 0.1434 | G19: =VALUE('disclosed1-1'!D19) -> 0.2218 | H19: =VALUE('disclosed1-1'!E19) -> 0.0006942
E20: =VALUE('disclosed1-1'!B20) -> -0.3786 | F20: =VALUE('disclosed1-1'!C20) -> -0.3504 | G20: =VALUE('disclosed1-1'!D20) -> -0.4154 | H20: =VALUE('disclosed1-1'!E20) -> -0.02634
C21: 3+ | D21: ='disclosed1-1'!A21 -> czcnt3 | E21: =VALUE('disclosed1-1'!B21) -> 0.04057 | F21: =VALUE('disclosed1-1'!C21) -> 0.03259 | G21: =VALUE('disclosed1-1'!D21) -> 0.05341 | H21: =VALUE('disclosed1-1'!E21) -> 0
E22: =VALUE('disclosed1-1'!B22) -> -0.1973 | F22: =VALUE('disclosed1-1'!C22) -> -0.1776 | G22: =VALUE('disclosed1-1'!D22) -> -0.2248 | H22: =VALUE('disclosed1-1'!E22) -> 0
B23: Number of industry switches (within CZs):
C24: 0 | D24: ='disclosed1-1'!A23 -> naics4dswitch0 | E24: =VALUE('disclosed1-1'!B23) -> 0.6166 | F24: 1 | G24: =VALUE('disclosed1-1'!D23) -> 0 | H24: =VALUE('disclosed1-1'!E23) -> 0
E25: =VALUE('disclosed1-1'!B24) -> -0.4862 | F25: =VALUE('disclosed1-1'!C24) -> 0 | G25: =VALUE('disclosed1-1'!D24) -> 0 | H25: =VALUE('disclosed1-1'!E24) -> 0
C26: 1 | D26: ='disclosed1-1'!A25 -> naics4dswitch1 | E26: =VALUE('disclosed1-1'!B25) -> 0.2607 | F26: =VALUE('disclosed1-1'!C25) -> 0 | G26: =VALUE('disclosed1-1'!D25) -> 0.68 | H26: 1
E27: =VALUE('disclosed1-1'!B26) -> -0.439 | F27: =VALUE('disclosed1-1'!C26) -> 0 | G27: =VALUE('disclosed1-1'!D26) -> -0.4665 | H27: =VALUE('disclosed1-1'!E26) -> 0
C28: 2+ | D28: ='disclosed1-1'!A27 -> naics4dswitch2 | E28: =VALUE('disclosed1-1'!B27) -> 0.1227 | F28: =VALUE('disclosed1-1'!C27) -> 0 | G28: =VALUE('disclosed1-1'!D27) -> 0.32 | H28: =VALUE('disclosed1-1'!E27) -> 0
E29: =VALUE('disclosed1-1'!B28) -> -0.3281 | F29: =VALUE('disclosed1-1'!C28) -> 0 | G29: =VALUE('disclosed1-1'!D28) -> -0.4665 | H29: =VALUE('disclosed1-1'!E28) -> 0
B30: Mean number of quarters observed | D30: ='disclosed1-1'!A29 -> qobserved | E30: =VALUE('disclosed1-1'!B29) -> 25.85 | F30: =VALUE('disclosed1-1'!C29) -> 27.19 | G30: =VALUE('disclosed1-1'!D29) -> 23.7 | H30: =VALUE('disclosed1-1'!E29) -> 10.01
B31: (standard deviation) | E31: =VALUE('disclosed1-1'!B30) -> -7.683 | F31: =VALUE('disclosed1-1'!C30) -> -7.757 | G31: =VALUE('disclosed1-1'!D30) -> -7.045 | H31: =VALUE('disclosed1-1'!E30) -> -0.2634
B32: Number of person-quarter obs. (millions) | D32: ='disclosed1-1'!A31 -> Observations | E32: =VALUE('disclosed1-1'!B31)/1000000 -> 2505 | F32: =VALUE('disclosed1-1'!C31)/1000000 -> 1544 | G32: =VALUE('disclosed1-1'!D31)/1000000 -> 960.4 | H32: =VALUE('disclosed1-1'!E31)/1000000 -> 87.39
B33: Number of unique people (millions) | D33: ='disclosed1-1'!A32 -> Unique PIKs | E33: =VALUE('disclosed1-1'!B32)/1000000 -> 111.7 | F33: =VALUE('disclosed1-1'!C32)/1000000 -> 65.67 | G33: =VALUE('disclosed1-1'!D32)/1000000 -> 46.05 | H33: =VALUE('disclosed1-1'!E32)/1000000 -> 8.736
B35: Notes: See text for discussion of sample derivation. "Industry switchers" in column 3 are people observed in more than one industry within a single CZ. "Industry stayers" in column 2 may be observed in multiple CZ's, potentially in different industries in each, but are observed in only one industry per CZ. Event study sample is comprised of workers who switch industries exactly once within a CZ, and are observed for at least five continuous quarters within the CZ before and after the switch.

Sheet table2
B2: Table 2: Mean Wages, Estimated Wage Premiums, and Estimated Worker Skills for 2-digit Industries
D3: Based on Data from LEHD | I3: Based on Data from ACS
D4: Percent of | E4: Mean | F4: Mean | G4: Mean | J4: Mean | K4: Mean
D5: Workforce | E5: Log | F5: Worker | G5: Industry | J5: Worker | K5: Industry
E6: Earnings | F6: Skill | G6: Premium | J6: Skill | K6: Premium
F7: (Mean | I7: Mean Log | J7: (Mean
B8: NAICS | C8: Industry Description | F8: Zero) | I8: Wage | J8: Zero)
D9: (1) | E9: (2) | F9: (3) | G9: (4) | I9: (5) | J9: (5) | K9: (6)
B10: ='t2'!A2 -> 11 | C10: Agriculture, Forestry, Fishing | D10: ='t2'!D2 -> 0.0057974318 | E10: ='t2'!E2 -> 9.119638 | F10: ='t2'!F2 -> -0.23639491 | G10: ='t2'!G2 -> 0.16001994 | I10: =+#REF! -> #REF! | J10: ='t2'!L2 -> -0.19985279 | K10: ='t2'!K2 -> 0.087610438
B11: ='t2'!A3 -> 21 | C11: Mining, Quarrying, Oil and Gas | D11: ='t2'!D3 -> 0.0069294511 | E11: ='t2'!E3 -> 9.9076929 | F11: ='t2'!F3 -> 0.078292206 | G11: ='t2'!G3 -> 0.62160186 | I11: =+#REF! -> #REF! | J11: ='t2'!L3 -> -0.020007471 | K11: ='t2'!K3 -> 0.6229651
B12: ='t2'!A4 -> 22 | C12: Utilities | D12: ='t2'!D4 -> 0.008941575 | E12: ='t2'!E4 -> 9.8835471 | F12: ='t2'!F4 -> 0.1957944 | G12: ='t2'!G4 -> 0.48822169 | I12: =+#REF! -> #REF! | J12: ='t2'!L4 -> 0.1092599 | K12: ='t2'!K4 -> 0.60447341
B13: ='t2'!A5 -> 23 | C13: Construction | D13: ='t2'!D5 -> 0.051243287 | E13: ='t2'!E5 -> 9.4804554 | F13: ='t2'!F5 -> 0.018735725 | G13: ='t2'!G5 -> 0.25197944 | I13: =+#REF! -> #REF! | J13: ='t2'!L5 -> -0.058517601 | K13: ='t2'!K5 -> 0.35374469
B14: ='t2'!A6 -> 31 | C14: Manufacturing | D14: ='t2'!D6 -> 0.12045356 | E14: ='t2'!E6 -> 9.4966835 | F14: ='t2'!F6 -> -0.054122381 | G14: ='t2'!G6 -> 0.35077908 | I14: =+#REF! -> #REF! | J14: ='t2'!L6 -> 0.016122887 | K14: ='t2'!K6 -> 0.37315267
B15: ='t2'!A7 -> 42 | C15: Wholesale Trade | D15: ='t2'!D7 -> 0.05215393 | E15: ='t2'!E7 -> 9.5765202 | F15: ='t2'!F7 -> 0.080336347 | G15: ='t2'!G7 -> 0.29539186 | I15: =+#REF! -> #REF! | J15: ='t2'!L7 -> 0.032295261 | K15: ='t2'!K7 -> 0.34781817
B16: ='t2'!A8 -> 44 | C16: Retail Trade | D16: ='t2'!D8 -> 0.086937323 | E16: ='t2'!E8 -> 9.1359558 | F16: ='t2'!F8 -> -0.15786937 | G16: ='t2'!G8 -> 0.10734527 | I16: =+#REF! -> #REF! | J16: ='t2'!L8 -> -0.14028744 | K16: ='t2'!K8 -> 0.13417928
B17: ='t2'!A9 -> 48 | C17: Transportation and Warehousing | D17: ='t2'!D9 -> 0.040178798 | E17: ='t2'!E9 -> 9.4009981 | F17: ='t2'!F9 -> -0.045566775 | G17: ='t2'!G9 -> 0.24470794 | I17: =+#REF! -> #REF! | J17: ='t2'!L9 -> -0.014589984 | K17: ='t2'!K9 -> 0.30663061
B18: ='t2'!A10 -> 51 | C18: Information | D18: ='t2'!D10 -> 0.026018279 | E18: ='t2'!E10 -> 9.7745929 | F18: ='t2'!F10 -> 0.1897753 | G18: ='t2'!G10 -> 0.38970665 | I18: =+#REF! -> #REF! | J18: ='t2'!L10 -> 0.11969135 | K18: ='t2'!K10 -> 0.43130851
B19: ='t2'!A11 -> 52 | C19: Finance and Insurance | D19: ='t2'!D11 -> 0.056744289 | E19: ='t2'!E11 -> 9.6926854 | F19: ='t2'!F11 -> 0.17488569 | G19: ='t2'!G11 -> 0.31782429 | I19: =+#REF! -> #REF! | J19: ='t2'!L11 -> 0.11905921 | K19: ='t2'!K11 -> 0.5190739
B20: ='t2'!A12 -> 53 | C20: Real Estate and Rental and Leasing | D20: ='t2'!D12 -> 0.015188341 | E20: ='t2'!E12 -> 9.3916469 | F20: ='t2'!F12 -> -0.027557533 | G20: ='t2'!G12 -> 0.22311722 | I20: =+#REF! -> #REF! | J20: ='t2'!L12 -> 0.050885566 | K20: ='t2'!K12 -> 0.29658061
B21: ='t2'!A13 -> 54 | C21: Professional, Scientific, Tech. | D21: ='t2'!D13 -> 0.075251035 | E21: ='t2'!E13 -> 9.7950068 | F21: ='t2'!F13 -> 0.27015549 | G21: ='t2'!G13 -> 0.32803653 | I21: =+#REF! -> #REF! | J21: ='t2'!L13 -> 0.2577993 | K21: ='t2'!K13 -> 0.47749209
... B29: ='t2'!A21 -> 92 | C29: Public Administration | D29: ='t2'!D21 -> 0.056624118 | E29: ='t2'!E21 -> 9.4710006 | F29: ='t2'!F21 -> -0.010014789 | G29: ='t2'!G21 -> 0.2789326 | I29: =+#REF! -> #REF! | J29: ='t2'!L21 -> 0.12519775 | K29: ='t2'!K21 -> 0.42675492
B30: Weighted std. dev. across sectors | D30: -- | E30: ='t2'!E22 -> 0.22078065 | F30: ='t2'!F22 -> 0.13721281 | G30: ='t2'!G22 -> 0.10443362 | H30: -- | I30: 0.25 | J30: ='t2'!L22 -> 0.13770522 | K30: ='t2'!K22 -> 0.14892778
B32: Notes: See text for descriptions of samples used in LEHD (columns 1-4) and ACS (columns 5-6). Entry in column 3 is average of estimated person effects from AKM models fit by CZ, normalized to have mean zero across all workers. Entry in column 4 is average wage premium, based on person-quarter weighted average of establishment premiums from AKM models fit by CZ, and normalized to have mean 0 in restaurants and eating places (NAICS 7225). Entry in column 5 is mean of estimated wage index (Xθ) from cross sectional regression model, normalized to have mean zero across all workers. Entry in column 6 is mean of estimated industry effects for industries in the 2-digit sector from cross sectional regression model, normalized to have mean of 0.04 in accommodation and food services.

Sheet table3
F2: Table 3: Mean Wages, Estimated Wage Premiums, and Estimated Worker Skills for 3-digit manufacturing Industries
H3: Based on Data from LEHD | M3: Based on Data from ACS
H4: Percent of | I4: Mean | J4: Mean | K4: Mean | M4: Mean | N4: Mean
H5: Workforce | I5: Log | J5: Worker | K5: Industry | M5: Worker | N5: Industry
I6: Earnings | J6: Skill | K6: Premium | M6: Skill | N6: Premium
J7: (Mean | M7: (Mean
F8: NAICS | G8: Industry Description | J8: Zero) | M8: Zero)
H9: (1) | I9: (2) | J9: (3) | K9: (4) | M9: (5) | N9: (6)
F10: 311-2 | G10: Food and kindred products | H10: ='t3'!C2/SUM('t2'!$C$2:$C$21) -> 0.015261001 | I10: ='t3'!E2 -> 9.2838179 | J10: ='t3'!F2 -> -0.24407361 | K10: ='t3'!G2 -> 0.32482625 | M10: ='t3'!L2 -> -0.12964387 | N10: ='t3'!K2 -> 0.27415311
F11: 313-4 | G11: Textile mill products | H11: ='t3'!C3/SUM('t2'!$C$2:$C$21) -> 0.0020740046 | I11: ='t3'!E3 -> 9.1369249 | J11: ='t3'!F3 -> -0.29171222 | K11: ='t3'!G3 -> 0.22304441 | M11: ='t3'!L3 -> -0.1362257 | N11: ='t3'!K3 -> 0.22885813
F12: 315-6 | G12: Apparel and leather | H12: ='t3'!C4/SUM('t2'!$C$2:$C$21) -> 0.0011845181 | I12: ='t3'!E4 -> 9.0988959 | J12: ='t3'!F4 -> -0.22897443 | K12: ='t3'!G4 -> 0.1466246 | M12: ='t3'!L4 -> -0.12995601 | N12: ='t3'!K4 -> 0.14716405
F13: 321 | G13: Wood Products | H13: ='t3'!C5/SUM('t2'!$C$2:$C$21) -> 0.0031790758 | I13: ='t3'!E5 -> 9.2031955 | J13: ='t3'!F5 -> -0.22424467 | K13: ='t3'!G5 -> 0.2177352 | M13: ='t3'!L5 -> -0.10726997 | N13: ='t3'!K5 -> 0.21257707
F14: 322 | G14: Paper | H14: ='t3'!C6/SUM('t2'!$C$2:$C$21) -> 0.0040529923 | I14: ='t3'!E6 -> 9.5325463 | J14: ='t3'!F6 -> -0.095454685 | K14: ='t3'!G6 -> 0.42831864 | M14: ='t3'!L6 -> -0.0038604476 | N14: ='t3'!K6 -> 0.43684211
F15: 323 | G15: Printing and Related | H15: ='t3'!C7/SUM('t2'!$C$2:$C$21) -> 0.0042198708 | I15: ='t3'!E7 -> 9.282 | J15: ='t3'!F7 -> -0.12726025 | K15: ='t3'!G7 -> 0.2163 | M15: ='t3'!L7 -> -0.0018905663 | N15: ='t3'!K7 -> 0.26059794
F16: 324 | G16: Petroleum and Coal | H16: ='t3'!C8/SUM('t2'!$C$2:$C$21) -> 0.0013050859 | I16: ='t3'!E8 -> 10.05 | J16: ='t3'!F8 -> 0.21973975 | K16: ='t3'!G8 -> 0.6214 | M16: ='t3'!L8 -> 0.10419235 | N16: ='t3'!K8 -> 0.69355416
F17: 325 | G17: Chemicals | H17: ='t3'!C9/SUM('t2'!$C$2:$C$21) -> 0.0085846625 | I17: ='t3'!E9 -> 9.7771006 | J17: ='t3'!F9 -> 0.10552467 | K17: ='t3'!G9 -> 0.46533688 | M17: ='t3'!L9 -> 0.14170207 | N17: ='t3'!K9 -> 0.51985294
F18: 326 | G18: Plastics and Rubber | H18: ='t3'!C10/SUM('t2'!$C$2:$C$21) -> 0.0066935056 | I18: ='t3'!E10 -> 9.3204719 | J18: ='t3'!F10 -> -0.19119857 | K18: ='t3'!G10 -> 0.30308083 | M18: ='t3'!L10 -> -0.06159072 | N18: ='t3'!K10 -> 0.30486643
F19: 327 | G19: Nonmetallic Minerals | H19: ='t3'!C11/SUM('t2'!$C$2:$C$21) -> 0.0037898991 | I19: ='t3'!E11 -> 9.4204772 | J19: ='t3'!F11 -> -0.12425814 | K19: ='t3'!G11 -> 0.33743568 | M19: ='t3'!L11 -> -0.032979824 | N19: ='t3'!K11 -> 0.33702356
F20: 331 | G20: Primary Metals | H20: ='t3'!C12/SUM('t2'!$C$2:$C$21) -> 0.0041212608 | I20: ='t3'!E12 -> 9.565383 | J20: ='t3'!F12 -> -0.11686336 | K20: ='t3'!G12 -> 0.48025375 | M20: ='t3'!L12 -> -0.024083862 | N20: ='t3'!K12 -> 0.42135847
F21: 332 | G21: Fabricated Metals | H21: ='t3'!C13/SUM('t2'!$C$2:$C$21) -> 0.013563072 | I21: ='t3'!E13 -> 9.3863793 | J21: ='t3'!F13 -> -0.0951076 | K21: ='t3'!G13 -> 0.2831072 | M21: ='t3'!L13 -> -0.030013798 | N21: ='t3'!K13 -> 0.32188016
F22: 333 | G22: Machinery | H22: ='t3'!C14/SUM('t2'!$C$2:$C$21) -> 0.011335364 | I22: ='t3'!E14 -> 9.5432986 | J22: ='t3'!F14 -> -0.0010662206 | K22: ='t3'!G14 -> 0.34283593 | M22: ='t3'!L14 -> 0.040200993 | N22: ='t3'!K14 -> 0.39938101
F23: 334 | G23: Computer and Electronic | H23: ='t3'!C15/SUM('t2'!$C$2:$C$21) -> 0.01162281 | I23: ='t3'!E15 -> 9.8615 | J23: ='t3'!F15 -> 0.26058221 | K23: ='t3'!G15 -> 0.42112437 | M23: ='t3'!L15 -> 0.25900835 | N23: ='t3'!K15 -> 0.50987136
F24: 335 | G24: Electrical Equipment | H24: ='t3'!C16/SUM('t2'!$C$2:$C$21) -> 0.0039978984 | I24: ='t3'!E16 -> 9.4776484 | J24: ='t3'!F16 -> -0.063004307 | K24: ='t3'!G16 -> 0.34009203 | M24: ='t3'!L16 -> 0.042388741 | N24: ='t3'!K16 -> 0.37804139
... F27: 339 | G27: Miscellaneous | H27: ='t3'!C19/SUM('t2'!$C$2:$C$21) -> 0.0055992137 | I27: ='t3'!E19 -> 9.4247356 | J27: ='t3'!F19 -> -0.054513298 | K27: ='t3'!G19 -> 0.28289634 | M27: ='t3'!L19 -> 0.020442761 | N27: ='t3'!K19 -> 0.31435332
F28: Weighted std. dev. across sectors | H28: -- | I28: ='t3'!E20 -> 0.21787692 | J28: ='t3'!F20 -> 0.15339325 | K28: ='t3'!G20 -> 0.087248246 | M28: ='t3'!L20 -> 0.10943842 | N28: ='t3'!K20 -> 0.10914908
F30: Notes: See notes to Table 2.

Sheet Table4
B2: Table 4. Relationships Between Worker Skills and Industry Wage Premiums
E4: Based on LEHD | I4: Based on Linked LEHD and ACS
B5: Explanatory Variable:
E6: -1 | F6: -2 | G6: -3 | I6: -4 | J6: -5 | K6: -6 | L6: -7 | M6: -8
B8: Mean earnings in industry | E8: =VALUE('t4'!B5) -> 0.6185 | F8: =VALUE('t4'!C5) -> 0.3722
E9: =VALUE('t4'!B6) -> -0.0194 | F9: =VALUE('t4'!C6) -> -0.0183
B11: Industry premium | G11: =VALUE('t4'!D8) -> 0.9012 | I11: =VALUE('t4'!E8) -> 0.9005 | K11: =VALUE('t4'!G8) -> 0.3299 | L11: =VALUE('t4'!H8) -> 0.6587 | M11: =VALUE('t4'!I8) -> 0.2418
G12: =VALUE('t4'!D9) -> -0.1226 | I12: =VALUE('t4'!E9) -> -0.1227 | K12: =VALUE('t4'!G9) -> -0.0997 | L12: =VALUE('t4'!H9) -> -0.1538 | M12: =VALUE('t4'!I9) -> -0.0827
B14: Skill index | J14: =VALUE('t4'!F11) -> 1.041 | K14: =VALUE('t4'!G11) -> 0.9017
J15: =VALUE('t4'!F12) -> -0.0698 | K15: =VALUE('t4'!G12) -> -0.0838
B16: Constant
B18: Num. observations | E18: =VALUE('t4'!B17) -> 311 | F18: =VALUE('t4'!C17) -> 311 | G18: =VALUE('t4'!D17) -> 311 | I18: =VALUE('t4'!E17) -> 310 | J18: =VALUE('t4'!F17) -> 310 | K18: =VALUE('t4'!G17) -> 310 | L18: =VALUE('t4'!H17) -> 310 | M18: =VALUE('t4'!I17) -> 310
B19: R-squared | E19: =VALUE('t4'!B18) -> 0.867 | F19: =VALUE('t4'!C18) -> 0.717 | G19: =VALUE('t4'!D18) -> 0.356 | I19: =VALUE('t4'!E18) -> 0.355 | J19: =VALUE('t4'!F18) -> 0.712 | K19: =VALUE('t4'!G18) -> 0.747 | L19: =VALUE('t4'!H18) -> 0.267 | M19: =VALUE('t4'!I18) -> 0.089
B21: Note: Each column is a separate regression model, estimated across 4-digit industries, with dependent variable in column heading. In columns 4-8 the sample excludes one industry (Central Banking) that cannot be linked to ACS. Skill index is constructed from ACS data and merged to 4-digit industry data from LEHD. All models are fit by weighted OLS, using the number of person-quarter observations in the industry in our LEHD sample as a weight. Robust standard errors in parentheses.

Sheet Table5
B3: Table 5. Worker Experience and the Industry Hierarchy Effect
C5: Young workers | F5: Older workers
C6: -1 | D6: -2 | F6: -3 | G6: -4
B7: Number of quarters in industry/10 | C7: =VALUE(SUBSTITUTE('disclosed1-12'!B6,"*",""))*10 -> 0.0119 | D7: =VALUE(SUBSTITUTE('disclosed1-12'!C6,"*",""))*10 -> 0.0101 | F7: =VALUE(SUBSTITUTE('disclosed1-12'!D6,"*",""))*10 -> 0.00702 | G7: =VALUE(SUBSTITUTE('disclosed1-12'!E6,"*",""))*10 -> 0.00587
C8: =VALUE(SUBSTITUTE('disclosed1-12'!B7,"*",""))*10 -> -0.00191 | D8: =VALUE(SUBSTITUTE('disclosed1-12'!C7,"*",""))*10 -> -0.000884 | F8: =VALUE(SUBSTITUTE('disclosed1-12'!D7,"*",""))*10 -> -0.00118 | G8: =VALUE(SUBSTITUTE('disclosed1-12'!E7,"*",""))*10 -> -0.000579
B9: Number of quarters in industry/10, squared | C9: =VALUE(SUBSTITUTE('disclosed1-12'!B9,"*",""))*100 -> -0.00328 | D9: =VALUE(SUBSTITUTE('disclosed1-12'!C9,"*",""))*100 -> -0.00293 | F9: =VALUE(SUBSTITUTE('disclosed1-12'!D9,"*",""))*100 -> -0.00161 | G9: =VALUE(SUBSTITUTE('disclosed1-12'!E9,"*",""))*100 -> -0.0016
C10: =VALUE(SUBSTITUTE('disclosed1-12'!B10,"*",""))*100 -> -0.000568 | D10: =VALUE(SUBSTITUTE('disclosed1-12'!C10,"*",""))*100 -> -0.000265 | F10: =VALUE(SUBSTITUTE('disclosed1-12'!D10,"*",""))*100 -> -0.000294 | G10: =VALUE(SUBSTITUTE('disclosed1-12'!E10,"*",""))*100 -> -0.000162
B11: Fixed effects for worker, CZ, industry, time | C11: N | D11: Y | F11: N | G11: Y
B12: Person-quarter observations (millions) | C12: =VALUE('disclosed1-12'!B18)/1000000 -> 89.76 | D12: =C12 -> 89.76 | F12: =VALUE('disclosed1-12'!D18)/1000000 -> 421.8 | G12: =F12 -> 421.8
B13: Adjusted R-squared | C13: =VALUE(SUBSTITUTE('disclosed1-12'!B12,"*","")) -> 0.000368 | D13: =VALUE(SUBSTITUTE('disclosed1-12'!C12,"*","")) -> 0.734 | F13: =VALUE(SUBSTITUTE('disclosed1-12'!D12,"*","")) -> 0.000173 | G13: =VALUE(SUBSTITUTE('disclosed1-12'!E12,"*","")) -> 0.837
B14: Experience (in quarters) at which slope=0 | C14: =-10*C7/(2*C9) -> 18.140244 | D14: =-10*D7/(2*D9) -> 17.235495 | F14: =-10*F7/(2*F9) -> 21.801242 | G14: =-10*G7/(2*G9) -> 18.34375
B15: Cumulative effect of 5 years of experience | C15: =2*C7+4*C9 -> 0.01068 | D15: =2*D7+4*D9 -> 0.00848 | F15: =2*F7+4*F9 -> 0.0076 | G15: =2*G7+4*G9 -> 0.00534
B17: Notes: Each column is a separate regression. Dependent variable in all columns is the hierarchy effect for a given worker in a given quarter (the difference between the workplace pay premium and the industry average pay premium). Young workers in columns 1-2 are those who were not yet 27 at the beginning of 2010; older workers are all others in our main sample. Industry experience is the cumulative number of quarters from 2010-Q1 to date that the worker has been observed in their current industry (including previous spells). Standard errors are clustered at the industry level.

Sheet Table6
B2: Table 6. Comparisons of Industry Effects from Alternative Models
D4: Preferred model | F4: Cross-sectional models (fit to ACS) | J4: Industry Mover models (fit to LEHD)
D5: -1 | F5: -2 | G5: -3 | H5: -4 | J5: -5 | K5: -6 | L5: -7
B6: Alternative model controls for:
C7: Person fixed effects | J7: X | K7: X | L7: X
C8: Year effects and age/experience | F8: X | G8: X | H8: X | J8: X | K8: X | L8: X
C9: Education, gender, and race/ethicity | F9: X | G9: X | H9: X
C10: Field of study and immigration | G10: X | H10: X
C11: CZ fixed effects | H11: X | K11: X
C12: Industry-by-CZ fixed effects | L12: X
B14: Standard deviation of industry effects | D14: =VALUE('disclosed1-5'!B12) -> 0.122 | F14: =VALUE('t6'!B14) -> 0.1887 | G14: =VALUE('t6'!C14) -> 0.1737 | H14: =VALUE('t6'!D14) -> 0.1692 | J14: =VALUE('disclosed1-5'!E11) -> 0.0788 | K14: =VALUE('disclosed1-5'!F11) -> 0.0787 | L14: =VALUE('disclosed1-5'!G11) -> 0.0824
B16: Regression of alternative model estimates on preferred model estimates (N=311) | D16: 1 | F16: =VALUE('t6'!B5) -> 1.239 | G16: =VALUE('t6'!C5) -> 1.1686 | H16: =VALUE('t6'!D5) -> 1.1659 | J16: =VALUE(SUBSTITUTE('disclosed1-5'!E6,"*","")) -> 0.621 | K16: =VALUE(SUBSTITUTE('disclosed1-5'!F6,"*","")) -> 0.618 | L16: =VALUE(SUBSTITUTE('disclosed1-5'!G6,"*","")) -> 0.658
F17: =VALUE('t6'!B6) -> -0.0728 | G17: =VALUE('t6'!C6) -> -0.0639 | H17: =VALUE('t6'!D6) -> -0.0571 | J17: =VALUE(SUBSTITUTE('disclosed1-5'!E7,"*","")) -> -0.0194 | K17: =VALUE(SUBSTITUTE('disclosed1-5'!F7,"*","")) -> -0.02 | L17: =VALUE(SUBSTITUTE('disclosed1-5'!G7,"*","")) -> -0.0147
B18: R2 (adjusted) | F18: =VALUE('t6'!B13) -> 0.644 | G18: =VALUE('t6'!C13) -> 0.676 | H18: =VALUE('t6'!D13) -> 0.709 | J18: =VALUE('disclosed1-5'!E10) -> 0.929 | K18: =VALUE('disclosed1-5'!F10) -> 0.924 | L18: =VALUE('disclosed1-5'!G10) -> 0.954
B20: Note: Preferred model is "ground-up" model, based on averages of firm effects from AKM specification. Regressions are of industry effects from alternative model on industry effects from preferred model, and are weighted by the number of person-quarter observations in the industry. Alternative models in columns 2-4 are fit to ACS, and include 222 NAICS codes (some combining 4 digit codes). These are then merged to 310 4-digit NAICS codes. Alternative models in columns 5-7 are fit to LEHD with person effects and 311 4-digit NAICS dummies, as well as year and age effects. Robust standard errors in parentheses.

Sheet Table7
B2: Table 7. Summaries of CZ-specific β Coefficients
D5: -1 | E5: -2 | F5: -3
B6: Mean | D6: =VALUE('disclosed1-9a'!B57) -> 0.88 | E6: =VALUE('disclosed1-9a'!B65) -> 0.863 | F6: =VALUE('disclosed1-9a'!B61) -> 0.7988
B7: Standard deviation | D7: =VALUE('disclosed1-9a'!B58) -> 0.0818 | E7: =VALUE('disclosed1-9a'!B66) -> 0.097 | F7: =VALUE('disclosed1-9a'!B62) -> 0.1341
B8: Sampling-error adjusted SD | D8: =SQRT(D7^2-'disclosed2-1'!B8) -> 0.07628591 | E8: =SQRT(E7^2-'disclosed2-1'!B9) -> 0.094200849 | F8: =SQRT(F7^2-'disclosed2-1'!B10) -> 0.11485996
B10: Regressions of β in column heading on β indicated in row:
B11: Models for
C12: Coefficient | E12: =VALUE(SUBSTITUTE('disclosed1-9a'!K57,"*","")) -> 0.355 | F12: =VALUE(SUBSTITUTE('disclosed1-9a'!H57,"*","")) -> 0.6166
C13: (Standard error) | E13: =VALUE('disclosed1-9a'!K58) -> -0.2067 | F13: =VALUE('disclosed1-9a'!H58) -> -0.2044
C14: R2 (within-region) | E14: ='T7-8calcs'!D78 -> 0.13827983 | F14: ='T7-8calcs'!E78 -> 0.25599107
B15: Models for
C16: Coefficient | D16: =VALUE(SUBSTITUTE('disclosed1-9a'!E65,"*","")) -> 0.4279 | F16: =VALUE(SUBSTITUTE('disclosed1-9a'!H65,"*","")) -> 1.144
C17: (Standard error) | D17: =VALUE('disclosed1-9a'!E66) -> -0.2222 | F17: =VALUE('disclosed1-9a'!H66) -> -0.1355
C18: R2 (within-region) | D18: =E14 -> 0.13827983 | F18: ='T7-8calcs'!E83 -> 0.74142834
B19: Models for
C20: Coefficient | D20: =VALUE(SUBSTITUTE('disclosed1-9a'!E61,"*","")) -> 0.4214 | E20: =VALUE(SUBSTITUTE('disclosed1-9a'!K61,"*","")) -> 0.6491
C21: (Standard error) | D21: =VALUE('disclosed1-9a'!E62) -> -0.09287 | E21: =VALUE('disclosed1-9a'!K62) -> -0.06223
C22: R2 (within-region) | D22: =F14 -> 0.25599107 | E22: =F18 -> 0.74142834
B24: Note: β coefficients are slopes of a CZ's estimated industry effects or industry average person effects with respect to the national industry effect or industry average person effect -- see text. Summary statistics are weighted by the number of person-quarter observations in each CZ. Regressions relate one of the β coefficients for a CZ to another β coefficient for the same CZ, and control for indicators for four regions and for each of approximately 10 composite CZ's. N≈60. Reported R-squared statistics indicate the share of the within-CZ variation in the β explained, among the 50 non-composite CZs. Regressions are weighted by the number of person-quarter observations in the CZ; and standard errors are heteroskedasticity-robust.

Sheet Table8
B3: Table 8. Bivariate Relationships Between Beta Coefficients and CZ Characteristics
G5: Dependent Variable:
E6: Mean | G6: theta(psi, psi) | M6: theta(alpha, psi) | S6: theta(alpha, alpha)
E7: [Std Dev.] | G7: Coefficient | H7: Adj R2 | I7: Actual R2 | J7: Incremental R2 | K7: R2 | N7: Adj R2 | O7: Actual R2 | P7: Incremental R2 | Q7: R2 | S7: Coefficient | T7: Adj R2 | U7: Actual R2 | W7: R2
E8: -1 | G8: -2 | H8: -3 | K8: -3 | M8: -4 | N8: -5 | S8: -4 | T8: -7 | W8: -5
B15: ln(city size) | D15: ='disclosed1-9a'!A45 -> lnN_c | E15: =VALUE('disclosed1-9a'!B45) -> 17.91 | G15: =VALUE(SUBSTITUTE('disclosed1-9a'!E45,"*","")) -> 0.02925 | H15: =VALUE('disclosed1-9a'!E47) -> 0.1073 | I15: =1-(((59-12-1)/(59-1))*(1-H15)) -> 0.29199655 | J15: =I15-'T7-8calcs'!C$73 -> 0.030619929 | K15: =J15/(1-'T7-8calcs'!C73) -> 0.041455402 | M15: =VALUE(SUBSTITUTE('disclosed1-9a'!H45,"*","")) -> 0.08542 | N15: =VALUE('disclosed1-9a'!H47) -> 0.6304 | O15: =1-(((59-12-1)/(59-1))*(1-N15)) -> 0.70686897 | P15: =O15-#REF! -> #REF! | Q15: =P15/(1-#REF!) -> #REF! | S15: =VALUE(SUBSTITUTE('disclosed1-9a'!K45,"*","")) -> 0.08752 | T15: =VALUE('disclosed1-9a'!K47) -> 0.7293 | U15: =1-(((59-12-1)/(59-1))*(1-T15)) -> 0.7853069 | V15: =U15-'T7-8calcs'!D$73 -> 0.21705358 | W15: =V15/(1-'T7-8calcs'!D$73) -> 0.50273364
E16: =VALUE('disclosed1-9a'!B46) -> 0.8355 | G16: =VALUE('disclosed1-9a'!E46) -> -0.02691 | M16: =VALUE('disclosed1-9a'!H46) -> -0.03135 | S16: =VALUE('disclosed1-9a'!K46) -> -0.01958
B17: Mean pay premium in CZ | D17: ='disclosed1-9a'!A17 -> psi_c | E17: =VALUE('disclosed1-9a'!B17) -> 0.2356 | G17: =VALUE(SUBSTITUTE('disclosed1-9a'!E17,"*","")) -> 1.861 | H17: =VALUE('disclosed1-9a'!E19) -> 0.7407 | I17: =1-(((59-12-1)/(59-1))*(1-H17)) -> 0.79434828 | J17: =I17-'T7-8calcs'!C$73 -> 0.53297165 | K17: =J17/(1-'T7-8calcs'!C73) -> 0.72157431 | M17: =VALUE(SUBSTITUTE('disclosed1-9a'!H17,"*","")) -> 1.401 | N17: =VALUE('disclosed1-9a'!H19) -> 0.6326 | O17: =1-(((59-12-1)/(59-1))*(1-N17)) -> 0.70861379 | P17: =O17-#REF! -> #REF! | Q17: =P17/(1-#REF!) -> #REF! | S17: =VALUE(SUBSTITUTE('disclosed1-9a'!K17,"*","")) -> 0.8843 | T17: =VALUE('disclosed1-9a'!K19) -> 0.5558 | U17: =1-(((59-12-1)/(59-1))*(1-T17)) -> 0.64770345 | V17: =U17-'T7-8calcs'!D$73 -> 0.079450132 | W17: =V17/(1-'T7-8calcs'!D$73) -> 0.18402025
E18: =VALUE('disclosed1-9a'!B18) -> 0.04349 | G18: =VALUE('disclosed1-9a'!E18) -> -0.2175 | M18: =VALUE('disclosed1-9a'!H18) -> -0.3538 | S18: =VALUE('disclosed1-9a'!K18) -> -0.355
B19: Share of firms with psis in Q1 and Q5 | D19: ='disclosed1-9a'!A33 -> s_psi_q1q5 | E19: =VALUE('disclosed1-9a'!B33) -> 0.3006 | G19: =VALUE(SUBSTITUTE('disclosed1-9a'!E33,"*","")) -> 0.8656 | H19: =VALUE('disclosed1-9a'!E35) -> 0.6955 | M19: =VALUE(SUBSTITUTE('disclosed1-9a'!H33,"*","")) -> 0.7861 | N19: =VALUE('disclosed1-9a'!H35) -> 0.6838 | S19: =VALUE(SUBSTITUTE('disclosed1-9a'!K33,"*","")) -> 0.5768 | T19: =VALUE('disclosed1-9a'!K35) -> 0.6467
E20: =VALUE('disclosed1-9a'!B34) -> 0.09014 | G20: =VALUE('disclosed1-9a'!E34) -> -0.1145 | M20: =VALUE('disclosed1-9a'!H34) -> -0.1539 | S20: =VALUE('disclosed1-9a'!K34) -> -0.1095
B21: Average person effect in CZ | D21: ='disclosed1-9a'!A5 -> alpha_c | E21: =VALUE('disclosed1-9a'!B5) -> 9.456 | G21: =VALUE(SUBSTITUTE('disclosed1-9a'!E5,"*","")) -> 0.199 | H21: =VALUE('disclosed1-9a'!E7) -> 0.1101 | I21: =1-(((59-12-1)/(59-1))*(1-H21)) -> 0.29421724 | J21: =I21-'T7-8calcs'!C$73 -> 0.032840619 | K21: =J21/(1-'T7-8calcs'!C73) -> 0.044461927 | M21: =VALUE(SUBSTITUTE('disclosed1-9a'!H5,"*","")) -> 0.7971 | N21: =VALUE('disclosed1-9a'!H7) -> 0.771 | O21: =1-(((59-12-1)/(59-1))*(1-N21)) -> 0.81837931 | P21: =O21-#REF! -> #REF! | Q21: =P21/(1-#REF!) -> #REF! | S21: =VALUE(SUBSTITUTE('disclosed1-9a'!K5,"*","")) -> 0.662 | T21: =VALUE('disclosed1-9a'!K7) -> 0.8177 | U21: =1-(((59-12-1)/(59-1))*(1-T21)) -> 0.85541724 | V21: =U21-'T7-8calcs'!D$73 -> 0.28716393 | W21: =V21/(1-'T7-8calcs'!D$73) -> 0.66512132
E22: =VALUE('disclosed1-9a'!B6) -> 0.1319 | G22: =VALUE('disclosed1-9a'!E6) -> -0.2203 | M22: =VALUE('disclosed1-9a'!H6) -> -0.1414 | S22: =VALUE('disclosed1-9a'!K6) -> -0.07046
B23: Share of workers with alphas in Q1 and Q5 | D23: ='disclosed1-9a'!A13 -> s_alpha_q1q5 | E23: =VALUE('disclosed1-9a'!B13) -> 0.3994 | G23: =VALUE(SUBSTITUTE('disclosed1-9a'!E13,"*","")) -> 0.5773 | H23: =VALUE('disclosed1-9a'!E15) -> 0.09661 | M23: =VALUE(SUBSTITUTE('disclosed1-9a'!H13,"*","")) -> 1.988 | N23: =VALUE('disclosed1-9a'!H15) -> 0.638 | S23: =VALUE(SUBSTITUTE('disclosed1-9a'!K13,"*","")) -> 1.967 | T23: =VALUE('disclosed1-9a'!K15) -> 0.7245
E24: =VALUE('disclosed1-9a'!B14) -> 0.03059 | G24: =VALUE('disclosed1-9a'!E14) -> -0.6396 | M24: =VALUE('disclosed1-9a'!H14) -> -0.3943 | S24: =VALUE('disclosed1-9a'!K14) -> -0.2481
B25: Expected average pay premiums and expected average worker skills, given industry composition:
C26: Expected mean pay premium in CZ | D26: ='disclosed1-9a'!A29 -> Epsi_c | E26: =VALUE('disclosed1-9a'!B29) -> 0.2356 | G26: =VALUE(SUBSTITUTE('disclosed1-9a'!E29,"*","")) -> 3.975 | H26: =VALUE('disclosed1-9a'!E31) -> 0.3325 | I26: =1-(((59-12-1)/(59-1))*(1-H26)) -> 0.47060345 | J26: =I26-'T7-8calcs'!C$73 -> 0.20922683 | K26: =J26/(1-'T7-8calcs'!C73) -> 0.28326591 | M26: =VALUE(SUBSTITUTE('disclosed1-9a'!H29,"*","")) -> 5.241 | N26: =VALUE('disclosed1-9a'!H31) -> 0.664 | O26: =1-(((59-12-1)/(59-1))*(1-N26)) -> 0.73351724 | P26: =O26-#REF! -> #REF! | Q26: =P26/(1-#REF!) -> #REF! | S26: =VALUE(SUBSTITUTE('disclosed1-9a'!K29,"*","")) -> 2.615 | T26: =VALUE('disclosed1-9a'!K31) -> 0.5299 | U26: =1-(((59-12-1)/(59-1))*(1-T26)) -> 0.62716207 | V26: =U26-'T7-8calcs'!D$73 -> 0.058908753 | W26: =V26/(1-'T7-8calcs'!D$73) -> 0.13644286
E27: =VALUE('disclosed1-9a'!B30) -> 0.0111 | G27: =VALUE('disclosed1-9a'!E30) -> -1.015 | M27: =VALUE('disclosed1-9a'!H30) -> -1.057 | S27: =VALUE('disclosed1-9a'!K30) -> -0.8646
C28: Expected share of firms with psis in Q1 and Q5 | D28: ='disclosed1-9a'!A53 -> Es_psi_q1q5 | E28: =VALUE('disclosed1-9a'!B53) -> 0.3006 | G28: =VALUE(SUBSTITUTE('disclosed1-9a'!E53,"*","")) -> 2.077 | H28: =VALUE('disclosed1-9a'!E55) -> 0.3229 | M28: =VALUE(SUBSTITUTE('disclosed1-9a'!H53,"*","")) -> 3.297 | N28: =VALUE('disclosed1-9a'!H55) -> 0.7335 | S28: =VALUE(SUBSTITUTE('disclosed1-9a'!K53,"*","")) -> 1.851 | T28: =VALUE('disclosed1-9a'!K55) -> 0.5938
E29: =VALUE('disclosed1-9a'!B54) -> 0.02114 | G29: =VALUE('disclosed1-9a'!E54) -> -0.5314 | M29: =VALUE('disclosed1-9a'!H54) -> -0.5127 | S29: =VALUE('disclosed1-9a'!K54) -> -0.4174
C30: Expected mean person effect in CZ | D30: ='disclosed1-9a'!A21 -> Ealpha_c | E30: =VALUE('disclosed1-9a'!B21) -> 9.456 | G30: =VALUE(SUBSTITUTE('disclosed1-9a'!E21,"*","")) -> 1.354 | H30: =VALUE('disclosed1-9a'!E23) -> 0.1886 | I30: =1-(((59-12-1)/(59-1))*(1-H30)) -> 0.35647586 | J30: =I30-'T7-8calcs'!C$73 -> 0.09509924 | K30: =J30/(1-'T7-8calcs'!C73) -> 0.128752 | M30: =VALUE(SUBSTITUTE('disclosed1-9a'!H21,"*","")) -> 3.393 | N30: =VALUE('disclosed1-9a'!H23) -> 0.7832 | O30: =1-(((59-12-1)/(59-1))*(1-N30)) -> 0.82805517 | P30: =O30-#REF! -> #REF! | Q30: =P30/(1-#REF!) -> #REF! | S30: =VALUE(SUBSTITUTE('disclosed1-9a'!K21,"*","")) -> 2.36 | T30: =VALUE('disclosed1-9a'!K23) -> 0.7184 | U30: =1-(((59-12-1)/(59-1))*(1-T30)) -> 0.77666207 | V30: =U30-'T7-8calcs'!D$73 -> 0.20840875 | W30: =V30/(1-'T7-8calcs'!D$73) -> 0.48271072
E31: =VALUE('disclosed1-9a'!B22) -> 0.03052 | G31: =VALUE('disclosed1-9a'!E22) -> -0.4808 | M31: =VALUE('disclosed1-9a'!H22) -> -0.4288 | S31: =VALUE('disclosed1-9a'!K22) -> -0.385
C32: Expected share of workers with alphas in Q1 and Q5 | D32: ='disclosed1-9a'!A25 -> Es_alpha_q1q5 | E32: =VALUE('disclosed1-9a'!B25) -> 0.3872 | G32: =VALUE(SUBSTITUTE('disclosed1-9a'!E25,"*","")) -> 1.957 | H32: =VALUE('disclosed1-9a'!E27) -> 0.08608 | M32: =VALUE(SUBSTITUTE('disclosed1-9a'!H25,"*","")) -> 8.593 | N32: =VALUE('disclosed1-9a'!H27) -> 0.6553 | S32: =VALUE(SUBSTITUTE('disclosed1-9a'!K25,"*","")) -> 7.019 | T32: =VALUE('disclosed1-9a'!K27) -> 0.6582
E33: =VALUE('disclosed1-9a'!B26) -> 0.009524 | G33: =VALUE('disclosed1-9a'!E26) -> -2.127 | M33: =VALUE('disclosed1-9a'!H26) -> -2.749 | S33: =VALUE('disclosed1-9a'!K26) -> -1.658
B34: Institutional features:
C35: Union coverage | D35: ='disclosed1-9a'!A41 -> coverage | E35: =VALUE('disclosed1-9a'!B41) -> 0.1303 | G35: =VALUE(SUBSTITUTE('disclosed1-9a'!E41,"*","")) -> 0.4496 | H35: =VALUE('disclosed1-9a'!E43) -> 0.08972 | I35: =1-(((59-12-1)/(59-1))*(1-H35)) -> 0.27805379 | J35: =I35-'T7-8calcs'!C$73 -> 0.016677171 | K35: =J35/(1-'T7-8calcs'!C73) -> 0.02257872 | M35: =VALUE(SUBSTITUTE('disclosed1-9a'!H41,"*","")) -> 0.1463 | N35: =VALUE('disclosed1-9a'!H43) -> 0.4906 | O35: =1-(((59-12-1)/(59-1))*(1-N35)) -> 0.5959931 | P35: =O35-#REF! -> #REF! | Q35: =P35/(1-#REF!) -> #REF! | S35: =VALUE(SUBSTITUTE('disclosed1-9a'!K41,"*","")) -> 0.6131 | T35: =VALUE('disclosed1-9a'!K43) -> 0.4823 | U35: =1-(((59-12-1)/(59-1))*(1-T35)) -> 0.58941034 | V35: =U35-'T7-8calcs'!D$73 -> 0.021157029 | W35: =V35/(1-'T7-8calcs'!D$73) -> 0.049003338
E36: =VALUE('disclosed1-9a'!B42) -> 0.06013 | G36: =VALUE('disclosed1-9a'!E42) -> -0.5278 | M36: =VALUE('disclosed1-9a'!H42) -> -0.4202 | S36: =VALUE('disclosed1-9a'!K42) -> -0.3628
C37: ln(minimum wage) | D37: ='disclosed1-9a'!A49 -> lnmw | E37: =VALUE('disclosed1-9a'!B49) -> 2.089 | G37: =VALUE(SUBSTITUTE('disclosed1-9a'!E49,"*","")) -> 0.2417 | H37: =VALUE('disclosed1-9a'!E51) -> 0.1249 | I37: =1-(((59-12-1)/(59-1))*(1-H37)) -> 0.30595517 | J37: =I37-'T7-8calcs'!C$73 -> 0.04457855 | K37: =J37/(1-'T7-8calcs'!C73) -> 0.060353559 | M37: =VALUE(SUBSTITUTE('disclosed1-9a'!H49,"*","")) -> 0.4666 | N37: =VALUE('disclosed1-9a'!H51) -> 0.5755 | O37: =1-(((59-12-1)/(59-1))*(1-N37)) -> 0.66332759 | P37: =O37-#REF! -> #REF! | Q37: =P37/(1-#REF!) -> #REF! | S37: =VALUE(SUBSTITUTE('disclosed1-9a'!K49,"*","")) -> 0.4191 | T37: =VALUE('disclosed1-9a'!K51) -> 0.5794 | U37: =1-(((59-12-1)/(59-1))*(1-T37)) -> 0.66642069 | V37: =U37-'T7-8calcs'!D$73 -> 0.098167374 | W37: =V37/(1-'T7-8calcs'!D$73) -> 0.22737262
E38: =VALUE('disclosed1-9a'!B50) -> 0.1112 | G38: =VALUE('disclosed1-9a'!E50) -> -0.1438 | M38: =VALUE('disclosed1-9a'!H50) -> -0.1342 | S38: =VALUE('disclosed1-9a'!K50) -> -0.09526
B40: Note: Each coefficient is from a regression of the column variable on the row variable, with additional controls for four regions and for each of approximately 10 composite CZs. N≈60. Regressions are weighted by the number of person-quarter observations in the CZ, and standard errors are heteroskedasticity-robust.

Sheet tab A-1
B2: Table A1: Summary of AKM Estimation Results
C4: Variance / covariance | D4: Std. Dev. | E4: Correlation | F4: Variance share
C5: (1) | D5: (2) | E5: (3) | F5: (4)
B6: Panel A: Average of CZ-level variances/covariances computed from CZ-level AKM models
B7: Log quarterly earnings | C7: =VALUE('disclosed2-4'!C4) -> 0.406 | D7: =SQRT(C7) -> 0.63718129 | F7: =+C7/D$7^2 -> 1
B9: Estimated person, establishment effects and covariates
B10: Person effects | C10: ='disclosed2-4'!C5 -> 0.274 | D10: =SQRT(C10) -> 0.52345009 | F10: =+C10/D$7^2 -> 0.67487685
B11: Establishment effects | C11: ='disclosed2-4'!C6 -> 0.04398 | D11: =SQRT(C11) -> 0.20971409 | F11: =+C11/D$7^2 -> 0.10832512
B12: Covariate index | C12: ='disclosed2-4'!C7 -> 0.01874 | D12: =SQRT(C12) -> 0.13689412 | F12: =+C12/D$7^2 -> 0.046157635
B13: Residual | C13: ='disclosed2-4'!C8 -> 0.04916 | D13: =SQRT(C13) -> 0.22172054 | F13: =+C13/D$7^2 -> 0.12108374
B14: Covariances
B15: (person effects, establishment effects) | C15: ='disclosed2-4'!C9/2 -> 0.01444 | E15: =C15/(D10*D11) -> 0.13154196 | F15: =2*C15/D$7^2 -> 0.071133005
B16: (person effects, covariate index) | C16: ='disclosed2-4'!C10/2 -> -0.00503 | E16: =C16/(D10*D12) -> -0.07019528 | F16: =2*C16/D$7^2 -> -0.024778325
B17: (establishment effects, covariate index) | C17: ='disclosed2-4'!C12/2 -> 0.0006565 | E17: =C17/(D11*D12) -> 0.022867691 | F17: =2*C17/D$7^2 -> 0.0032339901
B19: Panel B: Variances/covariances from national AKM model (Card, Rothstein, and Yi 2023)
B20: Log quarterly earnings | C20: =D20^2 -> 0.42588676 | D20: =VALUE('L3disclosure7-2'!B7) -> 0.6526 | F20: 1
B22: Estimated person, establishment effects and covariates
B23: Person effects | C23: =F23*C$20 -> 0.27444143 | D23: =SQRT(C23) -> 0.52387158 | F23: =VALUE('L3disclosure7-2'!B8) -> 0.6444
B24: Establishment effects | C24: =F24*C$20 -> 0.049658396 | D24: =SQRT(C24) -> 0.22284164 | F24: =VALUE('L3disclosure7-2'!B9) -> 0.1166
B25: Covariate index | C25: =F25*C$20 -> 0.018138517 | D25: =SQRT(C25) -> 0.13467931 | F25: =VALUE('L3disclosure7-2'!B10) -> 0.04259
B26: Residual | C26: =F26*C$20 -> 0.053874675 | D26: =SQRT(C26) -> 0.23210919 | F26: =VALUE('L3disclosure7-2'!B11) -> 0.1265
B27: Covariances
B28: (person effects, establishment effects) | C28: =F28*C$20/2 -> 0.021294338 | E28: =C28/(D23*D24) -> 0.18240761 | F28: =VALUE('L3disclosure7-2'!B12) -> 0.1
B29: (person effects, covariate index) | C29: =F29*C$20/2 -> -0.0070484259 | E29: =C29/(D23*D25) -> -0.099900213 | F29: =VALUE('L3disclosure7-2'!B13) -> -0.0331
B30: (establishment effects, covariate index) | C30: =F30*C$20/2 -> 0.00061434165 | E30: =C30/(F24*F25) -> 0.1237097 | F30: =VALUE('L3disclosure7-2'!B15) -> 0.002885
B32: Note: Table presents summaries of estimated AKM models. Panel A summarizes results from the primary models used in this paper, fit separately to each of approximately 60 CZs or regional aggregates. Panel B summarizes results from an alternative model that is fit to the entire U.S., as in Card, Rothstein, and Yi (2023). Total sample size is approximately 2.505 billion person-quarters.

Sheet tabA-2
B2: Appendix Table A-2. Industry Wage Premiums, Mean Worker Effects, and Average Pay, 4-Digit Industries
B4: NAICS | C4: Industry | D4: Mean log earnings | E4: Mean worker effect (normalized to mean 0) | F4: Industry premium | G4: Percent of workforce
D5: (1) | E5: (2) | F5: (3) | G5: (4)
C6: Across-industry mean | D6: =apptab2!A2 -> 9.4336428 | E6: =apptab2!B2 -> 9.4562602 | F6: =apptab2!C2 -> 0.23558897
C7: Across-industry SD | D7: =apptab2!A3 -> 0.27829195 | E7: =apptab2!B3 -> 0.18484385 | F7: =apptab2!C3 -> 0.12233035
B9: =apptab2!E4 -> 1111 | C9: Oilseed and Grain Farming | D9: =apptab2!A4 -> 9.216 | E9: =apptab2!B4 -> -0.14526024 | F9: =apptab2!C4 -> 0.1524 | G9: =apptab2!F4 -> 0.00030141935
B10: =apptab2!E5 -> 1112 | C10: Vegetable and Melon Farming | D10: =apptab2!A5 -> 9.12 | E10: =apptab2!B5 -> -0.21326025 | F10: =apptab2!C5 -> 0.1545 | G10: =apptab2!F5 -> 0.0004247817
B11: =apptab2!E6 -> 1113 | C11: Fruit and Tree Nut Farming | D11: =apptab2!A6 -> 9.013 | E11: =apptab2!B6 -> -0.27026024 | F11: =apptab2!C6 -> 0.1043 | G11: =apptab2!F6 -> 0.00060882716
B12: =apptab2!E7 -> 1114 | C12: Greenhouse, Nursery, and Floriculture | D12: =apptab2!A7 -> 9.032 | E12: =apptab2!B7 -> -0.26326025 | F12: =apptab2!C7 -> 0.1021 | G12: =apptab2!F7 -> 0.00080964033
B13: =apptab2!E8 -> 1119 | C13: Other Crop Farming | D13: =apptab2!A8 -> 9.113 | E13: =apptab2!B8 -> -0.21526025 | F13: =apptab2!C8 -> 0.1306 | G13: =apptab2!F8 -> 0.00033735012
B14: =apptab2!E9 -> 1121 | C14: Cattle Ranching and Farming | D14: =apptab2!A9 -> 9.108 | E14: =apptab2!B9 -> -0.27126026 | F14: =apptab2!C9 -> 0.1771 | G14: =apptab2!F9 -> 0.00079646567
B15: =apptab2!E10 -> 1122 | C15: Hog and Pig Farming | D15: =apptab2!A10 -> 9.159 | E15: =apptab2!B10 -> -0.32026026 | F15: =apptab2!C10 -> 0.2593 | G15: =apptab2!F10 -> 0.00022516624
B16: =apptab2!E11 -> 1123 | C16: Poultry and Egg Production | D16: =apptab2!A11 -> 9.143 | E16: =apptab2!B11 -> -0.30726025 | F16: =apptab2!C11 -> 0.2355 | G16: =apptab2!F11 -> 0.00029423318
B17: =apptab2!E12 -> 1124 | C17: Sheep and Goat Farming | D17: =apptab2!A12 -> 9.019 | E17: =apptab2!B12 -> -0.25426024 | F17: =apptab2!C12 -> 0.08397 | G17: =apptab2!F12 -> 6.9865409e-06
B18: =apptab2!E13 -> 1125 | C18: Aquaculture | D18: =apptab2!A13 -> 9.185 | E18: =apptab2!B13 -> -0.15226024 | F18: =apptab2!C13 -> 0.1408 | G18: =apptab2!F13 -> 4.3116939e-05
B19: =apptab2!E14 -> 1129 | C19: Other Animal Production | D19: =apptab2!A14 -> 9.15 | E19: =apptab2!B14 -> -0.22926025 | F19: =apptab2!C14 -> 0.1739 | G19: =apptab2!F14 -> 0.0001161762
B20: =apptab2!E15 -> 1131 | C20: Timber Tract Operations | D20: =apptab2!A15 -> 9.555 | E20: =apptab2!B15 -> 0.075739756 | F20: =apptab2!C15 -> 0.2839 | G20: =apptab2!F15 -> 2.9343473e-05
... B47: =apptab2!E42 -> 3112 | C47: Grain and Oilseed Milling | D47: =apptab2!A42 -> 9.582 | E47: =apptab2!B42 -> -0.073260248 | F47: =apptab2!C42 -> 0.4492 | G47: =apptab2!F42 -> 0.00066591718
B48: Appendix Table A-2 (continued)
B50: NAICS | C50: Industry | D50: Mean log earnings | E50: Mean worker effect (normalized to mean 0) | F50: Industry premium | G50: Percent of workforce
D51: (1) | E51: (2) | F51: (3) | G51: (4)
B52: =apptab2!E43 -> 3113 | C52: Sugar and Confectionery Product Manuf. | D52: =apptab2!A43 -> 9.395 | E52: =apptab2!B43 -> -0.14926025 | F52: =apptab2!C43 -> 0.3478 | G52: =apptab2!F43 -> 0.00059445482
B53: =apptab2!E44 -> 3114 | C53: Fruit & Veg. Prsrvng. & Spec. Food Manuf. | D53: =apptab2!A44 -> 9.278 | E53: =apptab2!B44 -> -0.24226025 | F53: =apptab2!C44 -> 0.3256 | G53: =apptab2!F44 -> 0.0015741675
B54: =apptab2!E45 -> 3115 | C54: Dairy Product Manufacturing | D54: =apptab2!A45 -> 9.457 | E54: =apptab2!B45 -> -0.15926024 | F54: =apptab2!C45 -> 0.4117 | G54: =apptab2!F45 -> 0.0014168705
B55: =apptab2!E46 -> 3116 | C55: Animal Slaughtering and Processing | D55: =apptab2!A46 -> 9.069 | E55: =apptab2!B46 -> -0.43426025 | F55: =apptab2!C46 -> 0.2927 | G55: =apptab2!F46 -> 0.0044234786
B56: =apptab2!E47 -> 3117 | C56: Seafood Product Preparation and Pkging. | D56: =apptab2!A47 -> 9.226 | E56: =apptab2!B47 -> -0.23126024 | F56: =apptab2!C47 -> 0.281 | G56: =apptab2!F47 -> 0.00024113548
B57: =apptab2!E48 -> 3118 | C57: Bakeries and Tortilla Manufacturing | D57: =apptab2!A48 -> 9.217 | E57: =apptab2!B48 -> -0.25826025 | F57: =apptab2!C48 -> 0.2816 | G57: =apptab2!F48 -> 0.0021394785
B58: =apptab2!E49 -> 3119 | C58: Other Food Manufacturing | D58: =apptab2!A49 -> 9.373 | E58: =apptab2!B49 -> -0.15726025 | F58: =apptab2!C49 -> 0.3261 | G58: =apptab2!F49 -> 0.0017178906
B59: =apptab2!E50 -> 3121 | C59: Beverage Manufacturing | D59: =apptab2!A50 -> 9.452 | E59: =apptab2!B50 -> -0.061260246 | F59: =apptab2!C50 -> 0.3102 | G59: =apptab2!F50 -> 0.0018264814
B60: =apptab2!E51 -> 3122 | C60: Tobacco Manufacturing | D60: =apptab2!A51 -> 9.702 | E60: =apptab2!B51 -> -0.034260247 | F60: =apptab2!C51 -> 0.533 | G60: =apptab2!F51 -> 0.00013454082
B61: =apptab2!E52 -> 3131 | C61: Fiber, Yarn, and Thread Mills | D61: =apptab2!A52 -> 9.057 | E61: =apptab2!B52 -> -0.39926025 | F61: =apptab2!C52 -> 0.2405 | G61: =apptab2!F52 -> 0.00026748472
B62: =apptab2!E53 -> 3132 | C62: Fabric Mills | D62: =apptab2!A53 -> 9.194 | E62: =apptab2!B53 -> -0.28226024 | F62: =apptab2!C53 -> 0.2699 | G62: =apptab2!F53 -> 0.00052738405
B63: =apptab2!E54 -> 3133 | C63: Textile & Fabric Finishing & Coating Mills | D63: =apptab2!A54 -> 9.219 | E63: =apptab2!B54 -> -0.20826025 | F63: =apptab2!C54 -> 0.2325 | G63: =apptab2!F54 -> 0.00028584935
... B93: =apptab2!E84 -> 3311 | C93: Iron and Steel Mills & Ferroalloy Manuf. | D93: =apptab2!A84 -> 9.822 | E93: =apptab2!B84 -> -0.040260248 | F93: =apptab2!C84 -> 0.661 | G93: =apptab2!F84 -> 0.00098610041
B94: Appendix Table A-2 (continued)
B96: NAICS | C96: Industry | D96: Mean log earnings | E96: Mean worker effect (normalized to mean 0) | F96: Industry premium | G96: Percent of workforce
D97: (1) | E97: (2) | F97: (3) | G97: (4)
B98: =apptab2!E85 -> 3312 | C98: Steel Product Manuf. from Purchased Steel | D98: =apptab2!A85 -> 9.526 | E98: =apptab2!B85 -> -0.11126025 | F98: =apptab2!C85 -> 0.4318 | G98: =apptab2!F85 -> 0.00060323795
B99: =apptab2!E86 -> 3313 | C99: Alumina and Aluminum | D99: =apptab2!A86 -> 9.546 | E99: =apptab2!B86 -> -0.15226024 | F99: =apptab2!C86 -> 0.4911 | G99: =apptab2!F86 -> 0.00063078484
B100: =apptab2!E87 -> 3314 | C100: Nonferrous Metal (except Aluminum) | D100: =apptab2!A87 -> 9.559 | E100: =apptab2!B87 -> -0.083260246 | F100: =apptab2!C87 -> 0.4412 | G100: =apptab2!F87 -> 0.00065913022
...

Sheet tab A-3
B3: Intermediate estimates | R3: Table A-3. Testing the Role of Industry Composition Effects
E4: Psi(j,c) on psi(j) | I4: Alpha(j,c) on psi(j) | M4: Alpha(j,c) on alpha(j) | T4: Psi(j,c) on psi(j) | X4: Alpha(j,c) on psi(j) | AB4: Alpha(j,c) on alpha(j)
E7: -1 | F7: -2 | G7: -2 | I7: -3 | K7: -4 | M7: -3 | O7: -4 | T7: -1 | U7: -2 | V7: -2 | X7: -3 | Z7: -4 | AB7: -3 | AD7: -4
B8: Mean firm effect in CZ | R8: Mean pay premium in CZ
C9: Actual | D9: ='disclosed1-9b'!A13 -> psi_c | E9: =VALUE(SUBSTITUTE('disclosed1-9b'!J13,"*","")) -> 1.783 | I9: =VALUE(SUBSTITUTE('disclosed1-9b'!J46,"*","")) -> 0.7555 | M9: =VALUE(SUBSTITUTE('disclosed1-9b'!J77,"*","")) -> 0.6578 | S9: Expected given industry shares | T9: =+E9+E11 -> 2.2343 | X9: =+I9+I11 -> 4.5045 | AB9: =+M9+M11 -> 1.9728
E10: =VALUE(SUBSTITUTE('disclosed1-9b'!J14,"*","")) -> -0.2366 | I10: =VALUE(SUBSTITUTE('disclosed1-9b'!J47,"*","")) -> -0.3991 | M10: =VALUE(SUBSTITUTE('disclosed1-9b'!J78,"*","")) -> -0.4173 | T10: =-1*SQRT((E12)^2 - (E10)^2) -> -0.97778139 | X10: =-1*SQRT((I12)^2 - (I10)^2) -> -1.2844237 | AB10: =-1*SQRT((M12)^2 - (M10)^2) -> -0.86067006
C11: Expected given industry share | D11: =+'disclosed1-9b'!A15 -> Epsi_c | E11: =VALUE(SUBSTITUTE('disclosed1-9b'!J15,"*","")) -> 0.4513 | I11: =VALUE(SUBSTITUTE('disclosed1-9b'!J48,"*","")) -> 3.749 | M11: =VALUE(SUBSTITUTE('disclosed1-9b'!J79,"*","")) -> 1.315 | S11: Actual - expected | T11: =+E9 -> 1.783 | X11: =+I9 -> 0.7555 | AB11: =+M9 -> 0.6578
E12: =VALUE(SUBSTITUTE('disclosed1-9b'!J16,"*","")) -> -1.006 | I12: =VALUE(SUBSTITUTE('disclosed1-9b'!J49,"*","")) -> -1.345 | M12: =VALUE(SUBSTITUTE('disclosed1-9b'!J80,"*","")) -> -0.9565 | T12: =E10 -> -0.2366 | X12: =I10 -> -0.3991 | AB12: =M10 -> -0.4173
B13: Share of firms with psis in Q1 and Q5
C14: Actual | D14: =+'disclosed1-9b'!A17 -> s_psi_q1q5 | F14: =VALUE(SUBSTITUTE('disclosed1-9b'!M17,"*","")) -> 0.8061 | J14: =VALUE(SUBSTITUTE('disclosed1-9b'!M50,"*","")) -> 0.4292 | N14: =VALUE(SUBSTITUTE('disclosed1-9b'!M81,"*","")) -> 0.4369
F15: =VALUE(SUBSTITUTE('disclosed1-9b'!M18,"*","")) -> -0.1235 | J15: =VALUE(SUBSTITUTE('disclosed1-9b'!M51,"*","")) -> -0.1594 | N15: =VALUE(SUBSTITUTE('disclosed1-9b'!M82,"*","")) -> -0.1311
C16: Expected given industry share | D16: =+'disclosed1-9b'!A19 -> Es_psi_q1q5 | F16: =VALUE(SUBSTITUTE('disclosed1-9b'!M19,"*","")) -> 0.4017 | J16: =VALUE(SUBSTITUTE('disclosed1-9b'!M52,"*","")) -> 2.405 | N16: =VALUE(SUBSTITUTE('disclosed1-9b'!M83,"*","")) -> 0.9435
F17: =VALUE(SUBSTITUTE('disclosed1-9b'!M20,"*","")) -> -0.4592 | J17: =VALUE(SUBSTITUTE('disclosed1-9b'!M53,"*","")) -> -0.6118 | N17: =VALUE(SUBSTITUTE('disclosed1-9b'!M84,"*","")) -> -0.4655
B18: Average person effect in CZ | R18: Average person effect in CZ
C19: Actual | D19: =+'disclosed1-9b'!A5 -> alpha_c | G19: =VALUE(SUBSTITUTE('disclosed1-9b'!D5,"*","")) -> -0.2305 | K19: =VALUE(SUBSTITUTE('disclosed1-9b'!D38,"*","")) -> 0.389 | O19: =VALUE(SUBSTITUTE('disclosed1-9b'!D69,"*","")) -> 0.6189 | S19: Expected given industry shares | V19: =+G19+G21 -> 1.9225 | Z19: =+K19+K21 -> 2.435 | AD19: =+O19+O21 -> 0.835
G20: =VALUE(SUBSTITUTE('disclosed1-9b'!D6,"*","")) -> -0.3905 | K20: =VALUE(SUBSTITUTE('disclosed1-9b'!D39,"*","")) -> -0.2155 | O20: =VALUE(SUBSTITUTE('disclosed1-9b'!D70,"*","")) -> -0.1088 | V20: =-1*SQRT((G22)^2 - (G20)^2) -> -1.2347205 | Z20: =-1*SQRT((K22)^2 - (K20)^2) -> -0.72682554 | AD20: =-1*SQRT((O22)^2 - (O20)^2) -> -0.33423765
C21: Expected given industry share | D21: =+'disclosed1-9b'!A7 -> Ealpha_c | G21: =VALUE(SUBSTITUTE('disclosed1-9b'!D7,"*","")) -> 2.153 | K21: =VALUE(SUBSTITUTE('disclosed1-9b'!D40,"*","")) -> 2.046 | O21: =VALUE(SUBSTITUTE('disclosed1-9b'!D71,"*","")) -> 0.2161 | S21: Actual - expected | V21: =+G19 -> -0.2305 | Z21: =+K19 -> 0.389 | AD21: =+O19 -> 0.6189
G22: =VALUE(SUBSTITUTE('disclosed1-9b'!D8,"*","")) -> -1.295 | K22: =VALUE(SUBSTITUTE('disclosed1-9b'!D41,"*","")) -> -0.7581 | O22: =VALUE(SUBSTITUTE('disclosed1-9b'!D72,"*","")) -> -0.3515 | V22: =G20 -> -0.3905 | Z22: =K20 -> -0.2155 | AD22: =O20 -> -0.1088
B23: Share of workers with alphas in Q1 and Q5
C24: Actual | D24: =+'disclosed1-9b'!A9 -> s_alpha_q1q5 | H24: =VALUE(SUBSTITUTE('disclosed1-9b'!G9,"*","")) -> 0.4509 | L24: =VALUE(SUBSTITUTE('disclosed1-9b'!G42,"*","")) -> 1.178 | P24: =VALUE(SUBSTITUTE('disclosed1-9b'!G73,"*","")) -> 1.465
H25: =VALUE(SUBSTITUTE('disclosed1-9b'!G10,"*","")) -> -0.8431 | L25: =VALUE(SUBSTITUTE('disclosed1-9b'!G43,"*","")) -> -0.7429 | P25: =VALUE(SUBSTITUTE('disclosed1-9b'!G74,"*","")) -> -0.3986
C26: Expected given industry share | D26: =+'disclosed1-9b'!A11 -> Es_alpha_q1q5 | H26: =VALUE(SUBSTITUTE('disclosed1-9b'!G11,"*","")) -> 0.917 | L26: =VALUE(SUBSTITUTE('disclosed1-9b'!G44,"*","")) -> 5.875 | P26: =VALUE(SUBSTITUTE('disclosed1-9b'!G75,"*","")) -> 3.639
H27: =VALUE(SUBSTITUTE('disclosed1-9b'!G12,"*","")) -> -2.808 | L27: =VALUE(SUBSTITUTE('disclosed1-9b'!G45,"*","")) -> -3.957 | P27: =VALUE(SUBSTITUTE('disclosed1-9b'!G76,"*","")) -> -1.986
B29: R2 | E29: =1-(1-VALUE('disclosed1-9b'!J29))*(59-14-1)/(59-1) -> 0.80063448 | F29: =1-(1-VALUE('disclosed1-9b'!M29))*(59-14-1)/(59-1) -> 0.769 | G29: =1-(1-VALUE('disclosed1-9b'!D29))*(59-14-1)/(59-1) -> 0.38566897 | H29: =1-(1-VALUE('disclosed1-9b'!G29))*(59-14-1)/(59-1) -> 0.3017731 | I29: =1-(1-VALUE('disclosed1-9b'!J60))*(59-14-1)/(59-1) -> 0.76057931 | J29: =1-(1-VALUE('disclosed1-9b'!M60))*(59-14-1)/(59-1) -> 0.82430345 | K29: =1-(1-VALUE('disclosed1-9b'!D60))*(59-14-1)/(59-1) -> 0.84789655 | L29: =1-(1-VALUE('disclosed1-9b'!G60))*(59-14-1)/(59-1) -> 0.7602 | M29: =1-(1-VALUE('disclosed1-9b'!J93))*(59-14-1)/(59-1) -> 0.66605517 | N29: =1-(1-VALUE('disclosed1-9b'!M93))*(59-14-1)/(59-1) -> 0.7463931 | O29: =1-(1-VALUE('disclosed1-9b'!D93))*(59-14-1)/(59-1) -> 0.85912414 | P29: =1-(1-VALUE('disclosed1-9b'!G93))*(59-14-1)/(59-1) -> 0.81633793 | R29: R-squared | T29: =E29 -> 0.80063448 | U29: =1-(1-VALUE('disclosed1-9b'!T29))*(59-14-1)/(59-1) -> 0.43831724 | V29: =G29 -> 0.38566897 | X29: =I29 -> 0.76057931 | Y29: =1-(1-VALUE('disclosed1-9b'!T60))*(59-14-1)/(59-1) -> 0.52297931 | Z29: =K29 -> 0.84789655 | AB29: =M29 -> 0.66605517 | AC29: =1-(1-VALUE('disclosed1-9b'!T93))*(59-14-1)/(59-1) -> 0.55309655 | AD29: =O29 -> 0.85912414
B30: R2 (adj) | E30: =VALUE(+'disclosed1-9b'!J29) -> 0.7372 | F30: =VALUE(+'disclosed1-9b'!M29) -> 0.6955 | G30: =VALUE(+'disclosed1-9b'!D29) -> 0.1902 | H30: =VALUE(+'disclosed1-9b'!G29) -> 0.07961 | I30: =VALUE(+'disclosed1-9b'!J60) -> 0.6844 | J30: =VALUE(+'disclosed1-9b'!M60) -> 0.7684 | K30: =VALUE(+'disclosed1-9b'!D60) -> 0.7995 | L30: =VALUE(+'disclosed1-9b'!G60) -> 0.6839 | M30: =VALUE(+'disclosed1-9b'!J93) -> 0.5598 | N30: =VALUE(+'disclosed1-9b'!M93) -> 0.6657 | O30: =VALUE(+'disclosed1-9b'!D93) -> 0.8143 | P30: =VALUE(+'disclosed1-9b'!G93) -> 0.7579 | R30: Adjusted R-squared | T30: =E30 -> 0.7372 | U30: =VALUE(+'disclosed1-9b'!T29) -> 0.2596 | V30: =G30 -> 0.1902 | X30: =I30 -> 0.6844 | Y30: =VALUE(+'disclosed1-9b'!T60) -> 0.3712 | Z30: =K30 -> 0.7995 | AB30: =M30 -> 0.5598 | AC30: =VALUE(+'disclosed1-9b'!T93) -> 0.4109 | AD30: =O30 -> 0.8143
B32: Note: N≈60. Each coefficient is from a regression of the column variable on the row variables, with indicators for four regions and for each of approximately 10 composite Czs. | R32: Note: N≈60. Each coefficient is from a regression of the column variable on the row variables, with indicators for four regions and for each of approximately 10 composite CZs. Standard errors are approximated.

Sheet T7-8calcs
A1: This sheet contains intermediate calculations to construct R2 statistics for the non-composite CZs in the samples, based on disclosed Census data
A4: ="Output 9a - Bivariate Regressions, Top59 100%" -> Output 9a - Bivariate Regressions, Top59 100%
A5: ="" | B5: ="(1)" -> (1) | C5: ="(2)" -> (2) | D5: ="(3)" -> (3) | E5: ="(4)" -> (4) | F5: ="(5)" -> (5) | G5: ="(6)" -> (6) | H5: ="(7)" -> (7) | I5: ="(8)" -> (8) | J5: ="(9)" -> (9) | K5: ="(10)" -> (10)
A6: ="" | B6: Mean/SD | C6: Dependent Variable: "b_pjc_pj" | F6: Dependent Variable: "b_ajc_pj" | I6: Dependent Variable: "b_ajc_aj"
A8: Theta - mean | C8: ='disclosed1-9a'!B57 -> 0.880 | D8: =C8 -> 0.880 | E8: =D8 -> 0.880 | F8: ='disclosed1-9a'!B61 -> .7988 | G8: =F8 -> .7988 | H8: =G8 -> .7988 | I8: ='disclosed1-9a'!B65 -> 0.863 | J8: =I8 -> 0.863 | K8: =J8 -> 0.863
A9: theta - SD | C9: ='disclosed1-9a'!B58 -> 0.0818 | D9: =C9 -> 0.0818 | E9: =D9 -> 0.0818 | F9: ='disclosed1-9a'!B62 -> .1341 | G9: =F9 -> .1341 | H9: =G9 -> .1341 | I9: ='disclosed1-9a'!B66 -> 0.0970 | J9: =I9 -> 0.0970 | K9: =J9 -> 0.0970
A11: ="Division-CZ dummies" -> Division-CZ dummies | C11: ="No" -> No | D11: ="Yes" -> Yes | E11: ="Yes" -> Yes | F11: ="No" -> No | G11: ="Yes" -> Yes | H11: ="Yes" -> Yes | I11: ="No" -> No | J11: ="Yes" -> Yes | K11: ="Yes" -> Yes
A12: ="Region dummies" -> Region dummies | C12: ="No" -> No | D12: ="No" -> No | E12: ="Yes" -> Yes | F12: ="No" -> No | G12: ="No" -> No | H12: ="Yes" -> Yes | I12: ="No" -> No | J12: ="No" -> No | K12: ="Yes" -> Yes
A13: ="N" -> N | B13: ='disclosed1-9a'!B72 -> 60 | C13: =B13 -> 60 | F13: =C13 -> 60 | I13: =F13 -> 60
A15: N | B15: 59
A16: k | B16: 12 | C16: 0 | D16: 9 | E16: 12 | F16: 0 | G16: 9 | H16: 12 | I16: 0 | J16: 9 | K16: 12
A17: Membership
A18: Original output
A19: beta | B19: ='disclosed1-9a'!B37 -> .1178 | C19: ='disclosed1-9a'!C37 -> .3291 | D19: ='disclosed1-9a'!D37 -> .6368 | E19: ='disclosed1-9a'!E37 -> .5403 | F19: ='disclosed1-9a'!F37 -> .2339 | G19: ='disclosed1-9a'!G37 -> .1561 | H19: ='disclosed1-9a'!H37 -> .256 | I19: ='disclosed1-9a'!I37 -> .1826 | ... K19: ='disclosed1-9a'!K37 -> .7034*
A20: SE | B20: ='disclosed1-9a'!B38 -> .05989 | C20: ='disclosed1-9a'!C38 -> (.2479) | D20: ='disclosed1-9a'!D38 -> (.4074) | E20: ='disclosed1-9a'!E38 -> (.5216) | F20: ='disclosed1-9a'!F38 -> (.4062) | G20: ='disclosed1-9a'!G38 -> (.3036) | H20: ='disclosed1-9a'!H38 -> (.4258) | I20: ='disclosed1-9a'!I38 -> (.326) | ... K20: ='disclosed1-9a'!K38 -> (.3592)
A21: r2 adj | C21: ='disclosed1-9a'!C39 -> .04148 | D21: ='disclosed1-9a'!D39 -> .1519 | E21: ='disclosed1-9a'!E39 -> .09966 | F21: ='disclosed1-9a'!F39 -> -.00644 | G21: ='disclosed1-9a'!G39 -> .5049 | H21: ='disclosed1-9a'!H39 -> .4926 | I21: ='disclosed1-9a'!I39 -> -.004619 | J21: ='disclosed1-9a'!J39 -> .4934 | K21: ='disclosed1-9a'!K39 -> .4911
A22: RMSE | C22: ='disclosed1-9a'!C40 -> .08012 | D22: ='disclosed1-9a'!D40 -> .07536 | E22: ='disclosed1-9a'!E40 -> .07765 | F22: ='disclosed1-9a'!F40 -> .1345 | G22: ='disclosed1-9a'!G40 -> .09436 | H22: ='disclosed1-9a'!H40 -> .09553 | I22: ='disclosed1-9a'!I40 -> .09725 | J22: ='disclosed1-9a'!J40 -> .06906 | K22: ='disclosed1-9a'!K40 -> .06921
A23: Calculations
A24: R2 of regression of X on controls | C24: 0 | D24: 0.5663 | E24: 0.8495 | F24: =+C24 -> 0 | G24: =+D24 -> 0.5663 | H24: =+E24 -> 0.8495 | I24: =+F24 -> 0 | J24: =+G24 -> 0.5663 | K24: =+H24 -> 0.8495
A25: R2 of regression of theta on X, Z | C25: =1-((($B$15-C$16-1)/($B$15-1))*(1-C21)) -> 0.04148 | D25: =1-((($B$15-D$16-1)/($B$15-1))*(1-D21)) -> 0.28350172 | E25: =1-((($B$15-E$16-1)/($B$15-1))*(1-E21)) -> 0.28593724 | F25: =1-((($B$15-F$16-1)/($B$15-1))*(1-F21)) -> -0.00644 | G25: =1-((($B$15-G$16-1)/($B$15-1))*(1-G21)) -> 0.58172586 | H25: =1-((($B$15-H$16-1)/($B$15-1))*(1-H21)) -> 0.59757931 | I25: =1-((($B$15-I$16-1)/($B$15-1))*(1-I21)) -> -0.004619 | J25: =1-((($B$15-J$16-1)/($B$15-1))*(1-J21)) -> 0.57201034 | K25: =1-((($B$15-K$16-1)/($B$15-1))*(1-K21)) -> 0.59638966
A26: V(xtilde) | C26: =(1-C24)*($B20^2) -> 0.0035868121 | D26: =(1-D24)*($B20^2) -> 0.0015556004 | E26: =(1-E24)*($B20^2) -> 0.00053981522 | F26: =(1-F24)*($B20^2) -> 0.0035868121 | G26: =(1-G24)*($B20^2) -> 0.0015556004 | H26: =(1-H24)*($B20^2) -> 0.00053981522 | I26: =(1-I24)*($B20^2) -> 0.0035868121 | J26: =(1-J24)*($B20^2) -> 0.0015556004 | K26: =(1-K24)*($B20^2) -> 0.00053981522
A27: V(prediction from regression of theta on X, Z) | C27: =C25*(C$9^2) -> 0.00027755264 | D27: =D25*(D$9^2) -> 0.0018969781 | E27: =E25*(E$9^2) -> 0.0019132747 | F27: =F25*(F$9^2) -> -0.0001158093 | G27: =G25*(G$9^2) -> 0.010461066 | H27: =H25*(H$9^2) -> 0.010746155 | I27: =I25*(I$9^2) -> -4.3460171e-05 | J27: =J25*(J$9^2) -> 0.0053820453 | K27: =K25*(K$9^2) -> 0.0056114303
A28: V(prediction from regression of theta on Z) | C28: =C27-C26*(VALUE(SUBSTITUTE(C19,"*",""))^2) -> -0.00011092354 | D28: =D27-D26*(VALUE(SUBSTITUTE(D19,"*",""))^2) -> 0.00126616 | E28: =E27-E26*(VALUE(SUBSTITUTE(E19,"*",""))^2) -> 0.0017556896 | F28: =F27-F26*(VALUE(SUBSTITUTE(F19,"*",""))^2) -> -0.00031204095 | G28: =G27-G26*(VALUE(SUBSTITUTE(G19,"*",""))^2) -> 0.01042316 | H28: =H27-H26*(VALUE(SUBSTITUTE(H19,"*",""))^2) -> 0.010710778 | I28: =I27-I26*(VALUE(SUBSTITUTE(I19,"*",""))^2) -> -0.00016305439 | J28: =J27-J26*(VALUE(SUBSTITUTE(J19,"*",""))^2) -> 0.0051272658 | K28: =K27-K26*(VALUE(SUBSTITUTE(K19,"*",""))^2) -> 0.005344345
A29: r2 of regression of theta on Z | C29: =C28/(C$9^2) -> -0.016577427 | D29: =D28/(D9^2) -> 0.18922651 | E29: =E28/(E9^2) -> 0.26238629 | F29: =F28/(F9^2) -> -0.01735218 | G29: =G28/(G9^2) -> 0.57961798 | H29: =H28/(H9^2) -> 0.59561202 | I29: =I28/(I9^2) -> -0.017329619 | J29: =J28/(J9^2) -> 0.54493207 | K29: =K28/(K9^2) -> 0.56800351
A32: Coveratge
A33: Original output
A34: beta | B34: ='disclosed1-9a'!B41 -> .1303 | C34: ='disclosed1-9a'!C41 -> .3196 | D34: ='disclosed1-9a'!D41 -> .605 | E34: ='disclosed1-9a'!E41 -> .4496 | F34: ='disclosed1-9a'!F41 -> .1881 | G34: ='disclosed1-9a'!G41 -> .1244 | H34: ='disclosed1-9a'!H41 -> .1463 | I34: ='disclosed1-9a'!I41 -> .1492 | ... K34: ='disclosed1-9a'!K41 -> .6131*
A35: SE | B35: ='disclosed1-9a'!B42 -> .06013 | C35: ='disclosed1-9a'!C42 -> (.2477) | D35: ='disclosed1-9a'!D42 -> (.4098) | E35: ='disclosed1-9a'!E42 -> (.5278) | F35: ='disclosed1-9a'!F42 -> (.4043) | G35: ='disclosed1-9a'!G42 -> (.3001) | H35: ='disclosed1-9a'!H42 -> (.4202) | I35: ='disclosed1-9a'!I42 -> (.3256) | ... K35: ='disclosed1-9a'!K42 -> (.3628)
